[2025-05-05T14:16:01.903+0000] {local_task_job_runner.py:123} INFO - ::group::Pre task execution logs
[2025-05-05T14:16:01.923+0000] {taskinstance.py:2613} INFO - Dependencies all met for dep_context=non-requeueable deps ti=<TaskInstance: ingest_resultats_csv.load_csv_with_sqlalchemy scheduled__2025-05-05T14:14:00+00:00 [queued]>
[2025-05-05T14:16:01.931+0000] {taskinstance.py:2613} INFO - Dependencies all met for dep_context=requeueable deps ti=<TaskInstance: ingest_resultats_csv.load_csv_with_sqlalchemy scheduled__2025-05-05T14:14:00+00:00 [queued]>
[2025-05-05T14:16:01.931+0000] {taskinstance.py:2866} INFO - Starting attempt 1 of 1
[2025-05-05T14:16:01.944+0000] {taskinstance.py:2889} INFO - Executing <Task(PythonOperator): load_csv_with_sqlalchemy> on 2025-05-05 14:14:00+00:00
[2025-05-05T14:16:01.951+0000] {warnings.py:112} WARNING - /home/***/.local/lib/python3.12/site-packages/***/task/task_runner/standard_task_runner.py:70: DeprecationWarning: This process (pid=320) is multi-threaded, use of fork() may lead to deadlocks in the child.
  pid = os.fork()

[2025-05-05T14:16:01.952+0000] {standard_task_runner.py:72} INFO - Started process 322 to run task
[2025-05-05T14:16:01.952+0000] {standard_task_runner.py:104} INFO - Running: ['***', 'tasks', 'run', 'ingest_resultats_csv', 'load_csv_with_sqlalchemy', 'scheduled__2025-05-05T14:14:00+00:00', '--job-id', '10', '--raw', '--subdir', 'DAGS_FOLDER/ingest_resultats_csv.py', '--cfg-path', '/tmp/tmp7vk528nm']
[2025-05-05T14:16:01.953+0000] {standard_task_runner.py:105} INFO - Job 10: Subtask load_csv_with_sqlalchemy
[2025-05-05T14:16:02.001+0000] {task_command.py:467} INFO - Running <TaskInstance: ingest_resultats_csv.load_csv_with_sqlalchemy scheduled__2025-05-05T14:14:00+00:00 [running]> on host 12a98bcc642b
[2025-05-05T14:16:02.082+0000] {taskinstance.py:3132} INFO - Exporting env vars: AIRFLOW_CTX_DAG_OWNER='***' AIRFLOW_CTX_DAG_ID='ingest_resultats_csv' AIRFLOW_CTX_TASK_ID='load_csv_with_sqlalchemy' AIRFLOW_CTX_EXECUTION_DATE='2025-05-05T14:14:00+00:00' AIRFLOW_CTX_TRY_NUMBER='1' AIRFLOW_CTX_DAG_RUN_ID='scheduled__2025-05-05T14:14:00+00:00'
[2025-05-05T14:16:02.083+0000] {logging_mixin.py:190} INFO - Task instance is in running state
[2025-05-05T14:16:02.083+0000] {logging_mixin.py:190} INFO -  Previous state of the Task instance: queued
[2025-05-05T14:16:02.083+0000] {logging_mixin.py:190} INFO - Current task name:load_csv_with_sqlalchemy state:running start_date:2025-05-05 14:16:01.924236+00:00
[2025-05-05T14:16:02.084+0000] {logging_mixin.py:190} INFO - Dag name:ingest_resultats_csv and current dag run status:running
[2025-05-05T14:16:02.084+0000] {taskinstance.py:731} INFO - ::endgroup::
[2025-05-05T14:16:02.565+0000] {warnings.py:112} WARNING - /opt/***/dags/ingest_resultats_csv.py:29: UserWarning: Parsing dates in %d/%m/%Y format when dayfirst=False (the default) was specified. Pass `dayfirst=True` or specify a format to silence this warning.
  df[col] = pd.to_datetime(df[col], errors='coerce')

[2025-05-05T14:16:02.585+0000] {taskinstance.py:3311} ERROR - Task failed with exception
Traceback (most recent call last):
  File "/home/airflow/.local/lib/python3.12/site-packages/airflow/models/taskinstance.py", line 767, in _execute_task
    result = _execute_callable(context=context, **execute_callable_kwargs)
             ^^^^^^^^^^^^^^^^^^^^^^^^^^^^^^^^^^^^^^^^^^^^^^^^^^^^^^^^^^^^^
  File "/home/airflow/.local/lib/python3.12/site-packages/airflow/models/taskinstance.py", line 733, in _execute_callable
    return ExecutionCallableRunner(
           ^^^^^^^^^^^^^^^^^^^^^^^^
  File "/home/airflow/.local/lib/python3.12/site-packages/airflow/utils/operator_helpers.py", line 252, in run
    return self.func(*args, **kwargs)
           ^^^^^^^^^^^^^^^^^^^^^^^^^^
  File "/home/airflow/.local/lib/python3.12/site-packages/airflow/models/baseoperator.py", line 417, in wrapper
    return func(self, *args, **kwargs)
           ^^^^^^^^^^^^^^^^^^^^^^^^^^^
  File "/home/airflow/.local/lib/python3.12/site-packages/airflow/operators/python.py", line 238, in execute
    return_value = self.execute_callable()
                   ^^^^^^^^^^^^^^^^^^^^^^^
  File "/home/airflow/.local/lib/python3.12/site-packages/airflow/operators/python.py", line 256, in execute_callable
    return runner.run(*self.op_args, **self.op_kwargs)
           ^^^^^^^^^^^^^^^^^^^^^^^^^^^^^^^^^^^^^^^^^^^
  File "/home/airflow/.local/lib/python3.12/site-packages/airflow/utils/operator_helpers.py", line 252, in run
    return self.func(*args, **kwargs)
           ^^^^^^^^^^^^^^^^^^^^^^^^^^
  File "/opt/airflow/dags/ingest_resultats_csv.py", line 37, in load_csv_data
    engine = pg_hook.get_sqlalchemy_engine()
             ^^^^^^^^^^^^^^^^^^^^^^^^^^^^^^^
  File "/home/airflow/.local/lib/python3.12/site-packages/airflow/providers/common/sql/hooks/sql.py", line 282, in get_sqlalchemy_engine
    url = self.sqlalchemy_url
          ^^^^^^^^^^^^^^^^^^^
  File "/home/airflow/.local/lib/python3.12/site-packages/airflow/providers/postgres/hooks/postgres.py", line 126, in sqlalchemy_url
    conn = self.get_connection(self.get_conn_id())
           ^^^^^^^^^^^^^^^^^^^^^^^^^^^^^^^^^^^^^^^
  File "/home/airflow/.local/lib/python3.12/site-packages/airflow/hooks/base.py", line 83, in get_connection
    conn = Connection.get_connection_from_secrets(conn_id)
           ^^^^^^^^^^^^^^^^^^^^^^^^^^^^^^^^^^^^^^^^^^^^^^^
  File "/home/airflow/.local/lib/python3.12/site-packages/airflow/models/connection.py", line 537, in get_connection_from_secrets
    raise AirflowNotFoundException(f"The conn_id `{conn_id}` isn't defined")
airflow.exceptions.AirflowNotFoundException: The conn_id `postgres_default` isn't defined
[2025-05-05T14:16:02.589+0000] {logging_mixin.py:190} INFO - Task instance in failure state
[2025-05-05T14:16:02.589+0000] {logging_mixin.py:190} INFO - Task start:2025-05-05 14:16:01.924236+00:00 end:2025-05-05 14:16:02.589093+00:00 duration:0.664857
[2025-05-05T14:16:02.589+0000] {logging_mixin.py:190} INFO - Task:<Task(PythonOperator): load_csv_with_sqlalchemy> dag:<DAG: ingest_resultats_csv> dagrun:<DagRun ingest_resultats_csv @ 2025-05-05 14:14:00+00:00: scheduled__2025-05-05T14:14:00+00:00, state:running, queued_at: 2025-05-05 14:16:00.599826+00:00. externally triggered: False>
[2025-05-05T14:16:02.590+0000] {logging_mixin.py:190} INFO - Failure caused by The conn_id `postgres_default` isn't defined
[2025-05-05T14:16:02.590+0000] {taskinstance.py:1225} INFO - Marking task as FAILED. dag_id=ingest_resultats_csv, task_id=load_csv_with_sqlalchemy, run_id=scheduled__2025-05-05T14:14:00+00:00, execution_date=20250505T141400, start_date=20250505T141601, end_date=20250505T141602
[2025-05-05T14:16:02.599+0000] {taskinstance.py:340} INFO - ::group::Post task execution logs
[2025-05-05T14:16:02.599+0000] {standard_task_runner.py:124} ERROR - Failed to execute job 10 for task load_csv_with_sqlalchemy (The conn_id `postgres_default` isn't defined; 322)
Traceback (most recent call last):
  File "/home/airflow/.local/lib/python3.12/site-packages/airflow/task/task_runner/standard_task_runner.py", line 117, in _start_by_fork
    ret = args.func(args, dag=self.dag)
          ^^^^^^^^^^^^^^^^^^^^^^^^^^^^^
  File "/home/airflow/.local/lib/python3.12/site-packages/airflow/cli/cli_config.py", line 49, in command
    return func(*args, **kwargs)
           ^^^^^^^^^^^^^^^^^^^^^
  File "/home/airflow/.local/lib/python3.12/site-packages/airflow/utils/cli.py", line 116, in wrapper
    return f(*args, **kwargs)
           ^^^^^^^^^^^^^^^^^^
  File "/home/airflow/.local/lib/python3.12/site-packages/airflow/cli/commands/task_command.py", line 483, in task_run
    task_return_code = _run_task_by_selected_method(args, _dag, ti)
                       ^^^^^^^^^^^^^^^^^^^^^^^^^^^^^^^^^^^^^^^^^^^^
  File "/home/airflow/.local/lib/python3.12/site-packages/airflow/cli/commands/task_command.py", line 256, in _run_task_by_selected_method
    return _run_raw_task(args, ti)
           ^^^^^^^^^^^^^^^^^^^^^^^
  File "/home/airflow/.local/lib/python3.12/site-packages/airflow/cli/commands/task_command.py", line 341, in _run_raw_task
    return ti._run_raw_task(
           ^^^^^^^^^^^^^^^^^
  File "/home/airflow/.local/lib/python3.12/site-packages/airflow/utils/session.py", line 97, in wrapper
    return func(*args, session=session, **kwargs)
           ^^^^^^^^^^^^^^^^^^^^^^^^^^^^^^^^^^^^^^
  File "/home/airflow/.local/lib/python3.12/site-packages/airflow/models/taskinstance.py", line 3005, in _run_raw_task
    return _run_raw_task(
           ^^^^^^^^^^^^^^
  File "/home/airflow/.local/lib/python3.12/site-packages/airflow/models/taskinstance.py", line 273, in _run_raw_task
    TaskInstance._execute_task_with_callbacks(
  File "/home/airflow/.local/lib/python3.12/site-packages/airflow/models/taskinstance.py", line 3159, in _execute_task_with_callbacks
    result = self._execute_task(context, task_orig)
             ^^^^^^^^^^^^^^^^^^^^^^^^^^^^^^^^^^^^^^
  File "/home/airflow/.local/lib/python3.12/site-packages/airflow/models/taskinstance.py", line 3183, in _execute_task
    return _execute_task(self, context, task_orig)
           ^^^^^^^^^^^^^^^^^^^^^^^^^^^^^^^^^^^^^^^
  File "/home/airflow/.local/lib/python3.12/site-packages/airflow/models/taskinstance.py", line 767, in _execute_task
    result = _execute_callable(context=context, **execute_callable_kwargs)
             ^^^^^^^^^^^^^^^^^^^^^^^^^^^^^^^^^^^^^^^^^^^^^^^^^^^^^^^^^^^^^
  File "/home/airflow/.local/lib/python3.12/site-packages/airflow/models/taskinstance.py", line 733, in _execute_callable
    return ExecutionCallableRunner(
           ^^^^^^^^^^^^^^^^^^^^^^^^
  File "/home/airflow/.local/lib/python3.12/site-packages/airflow/utils/operator_helpers.py", line 252, in run
    return self.func(*args, **kwargs)
           ^^^^^^^^^^^^^^^^^^^^^^^^^^
  File "/home/airflow/.local/lib/python3.12/site-packages/airflow/models/baseoperator.py", line 417, in wrapper
    return func(self, *args, **kwargs)
           ^^^^^^^^^^^^^^^^^^^^^^^^^^^
  File "/home/airflow/.local/lib/python3.12/site-packages/airflow/operators/python.py", line 238, in execute
    return_value = self.execute_callable()
                   ^^^^^^^^^^^^^^^^^^^^^^^
  File "/home/airflow/.local/lib/python3.12/site-packages/airflow/operators/python.py", line 256, in execute_callable
    return runner.run(*self.op_args, **self.op_kwargs)
           ^^^^^^^^^^^^^^^^^^^^^^^^^^^^^^^^^^^^^^^^^^^
  File "/home/airflow/.local/lib/python3.12/site-packages/airflow/utils/operator_helpers.py", line 252, in run
    return self.func(*args, **kwargs)
           ^^^^^^^^^^^^^^^^^^^^^^^^^^
  File "/opt/airflow/dags/ingest_resultats_csv.py", line 37, in load_csv_data
    engine = pg_hook.get_sqlalchemy_engine()
             ^^^^^^^^^^^^^^^^^^^^^^^^^^^^^^^
  File "/home/airflow/.local/lib/python3.12/site-packages/airflow/providers/common/sql/hooks/sql.py", line 282, in get_sqlalchemy_engine
    url = self.sqlalchemy_url
          ^^^^^^^^^^^^^^^^^^^
  File "/home/airflow/.local/lib/python3.12/site-packages/airflow/providers/postgres/hooks/postgres.py", line 126, in sqlalchemy_url
    conn = self.get_connection(self.get_conn_id())
           ^^^^^^^^^^^^^^^^^^^^^^^^^^^^^^^^^^^^^^^
  File "/home/airflow/.local/lib/python3.12/site-packages/airflow/hooks/base.py", line 83, in get_connection
    conn = Connection.get_connection_from_secrets(conn_id)
           ^^^^^^^^^^^^^^^^^^^^^^^^^^^^^^^^^^^^^^^^^^^^^^^
  File "/home/airflow/.local/lib/python3.12/site-packages/airflow/models/connection.py", line 537, in get_connection_from_secrets
    raise AirflowNotFoundException(f"The conn_id `{conn_id}` isn't defined")
airflow.exceptions.AirflowNotFoundException: The conn_id `postgres_default` isn't defined
[2025-05-05T14:16:02.627+0000] {local_task_job_runner.py:266} INFO - Task exited with return code 1
[2025-05-05T14:16:02.640+0000] {taskinstance.py:3895} INFO - 0 downstream tasks scheduled from follow-on schedule check
[2025-05-05T14:16:02.643+0000] {local_task_job_runner.py:245} INFO - ::endgroup::
